Workbook

Sheet Старт
A1: Старт: что делать по шагам
A2: Идите сверху вниз. В таблице 13 карточек, но для первого показа нужны 9 (лист «К Reddit», колонка «В наборе»). Остальные 4 лежат в конце таблицы и ждут.
A4: Шаг | B4: Что сделать | C4: Где в таблице | D4: Кто | E4: Усилие | F4: Статус
A5: 1 | B5: Второй круг чтения: прочитать все 13 карточек по-русски (cards-ru.md): там теперь отмечено, что я исправил по вашим замечаниям. Новые правки пишите под «Мои правки». | C5: Файл cards-ru.md. Правки: лист «Тексты», колонка U. | D5: вы | E5: среднее | F5: сделано
A6: 2 | B6: Ответить на 10 вопросов-решений (ниже). Одним словом на каждый. | C6: Этот лист, ниже. | D6: вы | E6: малое | F6: сделано
A7: 3 | B7: Картинки. A) Запустить fetch_images.py: Кантино, носорог, землетрясение. B) Прислать мне файлы, я соберу превью. C) Для Casa da Neve, Torres Vedras и Douro решить: своё фото или шаблон. Tripeiros и апельсины готовы. | C7: Лист «Картинки», «К Reddit» (колонка «Картинка»). | D7: вы, затем я | E7: среднее | F7: 1. Ты не дал мне этот скрипт. 2. Не могу определиться концептуальнО, нужно ли использовать такие картинки или интереснее генерированные в стиле азулеже или моем? Исходя из кконцепции проекта - твои рекомендации
A8: 4 | B8: Мосты. Открыть в Google Maps 8 мест и скопировать адрес и координаты в лист «Места» (колонки K–P), в P поставить «да»: Museu de Marinha, Torre de Belém, памятник Tripeiros, Café Martinho da Arcada, 17•56 в Гае, памятник Албукерки в Белеме, форт São Vicente, CIBA. | C8: Лист «Места». K название, L адрес, M и N координаты, O сайт, P проверено. | D8: вы | E8: среднее | F8: 1. Сайт объекта давай не будем указывать. Сайты часто меняются, кто захочет - перейдет в гугл карты и найдет. Что думаешь? Или я не прав?
A9: 5 | B9: Проверить факты с пометкой ⚠ по очереди карточек. Источники смотреть по фильтру id. | C9: «К Reddit», колонка «Факты». Ссылки: лист «Источники». | D9: вы, я помогаю | E9: большое | F9: нет
A10: 6 | B10: Португальский. Отправить хуки и истории 3–5 носителям. Файл для отправки я подготовлю по запросу. | C10: Лист «Тексты», колонки D, H, L. | D10: вы | E10: малое | F10: Я не смогу это сделать. Будем обкаытвать уже в реале и надеяться, что ИИ адекватно переведет
A11: 7 | B11: Прочитать условия использования картинок Gemini и правила выбранного сабреддита. | C11: — | D11: вы | E11: малое | F11: сделано
A12: 8 | B12: Поручить мне черновик поста (название, текст, раскрытие про ИИ, вопрос аудитории) и страницу для показа. | C12: — | D12: я | E12: малое | F12: в работе
A14: Решения владельца
A15: № | B15: Вопрос | C15: Мой вариант по умолчанию | F15: Ваш ответ
A16: 1 | B16: Метка носорога: documented (бой описан как факт) или legend (как в вашем design)? | C16: documented | F16: Documented
A17: 2 | B17: Алжубарроту: новый хук «25-летний коннетабль ушёл с совета и сам выбрал поле боя». Подходит? | C17: подходит | F17: Я бы что-то с численным превосходством сделал, чтобы показать их крутыми
A18: 3 | B18: Алжубарроту: «тяжёлая тема» нет или да? (в тексте нет крови) | C18: нет | F18: Не тяжелая
A19: 4 | B19: Вторая нить «Люди как мы» у Алжубарроту и Tripeiros: оставить? | C19: оставить | F19: Да
A20: 5 | B20: Голос проекта в «Подробнее»: «мы не нашли» или нейтрально? | C20: нейтрально | F20: Оставляем мы
A21: 6 | B21: Апельсиновая война: выбрать мост (форт в Элваше) или оставить карточку без моста? | C21: без моста пока | F21: Если это как-то связано - можно указать, только добавить примечание к мосту как связано именно
A22: 7 | B22: Casa da Neve, Torres Vedras, Douro: своё фото или шаблон превью? | C22: шаблон превью | F22: Где посмотреть? Не увидел у тебя нигде
A23: 8 | B23: Подпись ИИ-иллюстраций: «Иллюстрация, созданная ИИ по преданию, не историческое изображение». Подходит? | C23: подходит | F23: А это нужно, как думаешь? Какие практики, исходя из целей и ЦА моего проекта? Нужно ли это к каждому изображению писать?
A24: 9 | B24: Новые лимиты: история 40–90 слов, «Подробнее» до 250 (было 70 и 150). Принять? Тогда поправлю spec §7 и Zod. | C24: принять | F24: Принять, гораздо лучше.
A25: 10 | B25: Motim разделён на две карточки: основание Дору (douro-1756) и бунт. Оставляем? | C25: оставить | F25: Да, сдоработками. В файле отзыв оставил

Sheet К Reddit
A1: К публикации на Reddit: что проверить и поправить
A2: Набор из 9 лёгких карточек. Тяжёлые темы и карточки без моста придержаны. Колонка «Статус»: пометьте, когда сделано.
A4: Карточка | B4: В наборе | C4: Картинка | D4: Мост | E4: Факты и источники | F4: Язык и тон | G4: Статус
A5: cantino-1502 | B5: да | C5: Скачать «Cantino planisphere (1502).jpg» (fetch_images.py), проверить кадр превью. PD (Commons). | D5: Museu de Marinha: адрес, координаты, выставлена ли копия, часы. | E5: Как карта попала к Кантино (подкуп, покупка?). Письма Кантино не читаны. Цепочка Caverio → Waldseemüller по McIntosh и BnF; «дала имя Америке» общеизвестный факт, в найденных источниках явно не прочитан. Год находки в лавке. | F5: Вычитать PT, EN, RU. «Génova» и «talho» проверить носителем. | G5: нет
A6: rinoceronte-1515 | B6: да | C6: Гравюра Дюрера: Cleveland Open Access или Commons (fetch_images.py). | D6: Torre de Belém: полный адрес, официальный сайт, координаты. | E6: Судьба тела: версии расходятся (чучело папе или шкура сначала в Лиссабон); следов чучела не нашли. Метка documented: решение. Слон Ханно, 1514. | F6: Вычитать PT. «Подробнее» теперь 4 абзаца. | G6: нет
A7: tripeiros-1415 | B7: да | C7: Есть картинка (ИИ, азулежу). Проверить фахверк (в Порту гранит и сланец). Подпись стоит. Условия Gemini прочитать. | D7: Памятник Лагоа Энрикеша (1960): название, адрес, координаты, официальная страница. | E7: У Зурары не найдено. Голос «мы» оставлен по решению владельца. | F7: Вычитать PT. | G7: нет
A8: guerra-laranjas-1801 | B8: да | C8: Есть картинка (ИИ). Крепость как замок, а не звёздчатый форт (в превью обрезана). Ноги лошади проверить. | D8: Мост не выбран (Forte de Santa Luzia в Элваше не проверен). | E8: Предание: ветка апельсинов или цветов (источники расходятся). 18 дней, Норонья держал Элваш, Оливенса, ратификация 1817. Спросить себя: теперь понятно, зачем ветка? | F8: Новый хук. Вычитать PT («conta a tradição»). | G8: нет
A9: casa-da-neve-1782 | B9: да | C9: Свободного файла нет. Снять самому или шаблон превью. | D9: Café Martinho da Arcada: Praça do Comércio 3. Часы расходятся. Координаты. Сайт martinhodaarcada.pt. | E9: Год открытия 1778 или 1782 (в тексте оба); имя 1829 или 1845. Монополия на лёд (DN, getlisbon). Путь снега Эштрела, Лозан, Монтежунту. Ссора с Marrare (RTP). | F9: Вычитать PT. «Neveiro» и «хранитель льда» согласовать. | G9: нет
A10: douro-1756 | B10: да | C10: Фото marco pombalino с Commons (не искал) или шаблон превью. | D10: 17•56 Museu & Enoteca (Gaia): координаты, часы, адрес. | E10: Новая карточка. «Первая в мире демаркированная» подано как «часто называют». 335 столбов (1758, 1761), около 100 стоят. Бузина вырывалась против подделок; про цвет не заявлено. «Монополия на торговлю с Англией и Бразилией» из Taylor's. | F10: Вычитать PT. Хук про бузину: цепляет ли? | G10: нет
A11: elefantes-malaca-1511 | B11: да | C11: Рисунок «Malaca» Гаспара Корреи (Torre do Tombo): найти файл на Commons, лицензию снимка. | D11: Памятник Албукерки в Белеме: координаты, официальная страница (в источниках только блог). Запасной: Casa dos Bicos. | E11: Цитата Пиреша: в нескольких энциклопедиях, не в Suma Oriental. Число слонов, силы Албукерки (1000–1200), дата падения не названа. Первоисточники не читаны. | F11: Новый хук и история. Вычитать PT. | G11: нет
A12: torres-vedras-1810 | B12: да | C12: Карта Clements Library (лицензия) или фото форта на Commons. Файл не выбран. | D12: Центр интерпретации в форте São Vicente: координаты. Часы 10–13, 14–18, закрыт по понедельникам, 2 € (rhlt.pt). | E12: Силы Массена 50 000–61 000, число фортов (152?), «секретность» мягко. Ёмкость форта 2000/4000 (муниципалитет). | F12: Новый хук. Вычитать PT. | G12: нет
A13: aljubarrota-1385 | B13: да | C13: Миниатюра Froissart (BnF fr. 2643, f. 72): найти файл на Commons. | D13: CIBA (São Jorge): адрес, координаты, часы. | E13: Рвы и ямы известны по Froissart, у Лопеша и Айялы их нет («по Фруассару» в истории). 18 000 из слабого источника: заменить. «Час вечерни» через панно CIBA. Возраст Нуну вычислен. | F13: Хук и история переписаны. Вычитать PT. | G13: нет
A14: terramoto-1755 | B14: позже | C14: Гравюра 1755 г. (Commons) или панно «Grande Panorama de Lisboa» (лицензия снимка). | D14: Museu Arqueológico do Carmo: координаты, часы. | E14: Письмо короля: один источник, нужен Molesky. Высота цунами в Лиссабоне не найдена. | F14: Тяжёлая тема. Без правок. | G14: нет
A15: ponte-das-barcas-1809 | B15: позже | C15: Народная гравюра (Museu Soares dos Reis) или картина маслом: файл и лицензия. | D15: Alminhas da Ponte: координаты. Запасной: церковь Сан-Жозе-даш-Тайпаш. | E15: Число погибших (от сотен до 4000): теперь только в истории. «O Desastre» из блога. Свечи и месса из DN. | F15: Тяжёлая тема. Новый хук. | G15: нет
... A17: legiao-portuguesa-1812 | B17: позже | C17: Кандидата нет. | D17: Моста нет. | E17: «60 орденов Почётного легиона» не проверено. Алорна в Кёнигсберге: один источник. Слово «лучшие» убрано. | F17: Новый хук. | G17: нет
A19: Общее перед публикацией
A20: 1 | B20: Прочитать условия использования картинок сервиса (Gemini): коммерческое использование, атрибуция. | G20: нет
A21: 2 | B21: Прочитать правила выбранного сабреддита: ИИ-контент, самореклама, формат ссылок, нужны ли метки (я правил не смотрел). | G21: нет
A22: 3 | B22: Написать раскрытие: тексты написаны с помощью ИИ, факты сверены по открытым источникам, проект в бете. Не писать «проверено историком». | G22: нет
A23: 4 | B23: Показать 3–5 носителям португальского и спросить: есть ли неестественные фразы. | G23: нет
A24: 5 | B24: Закрыть координаты и адреса мостов у карточек набора. | G24: нет
A25: 6 | B25: Скачать картинки (fetch_images.py), проверить кадры превью 1200×630, подписать ИИ-иллюстрации. | G25: нет
A26: 7 | B26: Подготовить к каждой карточке 2–3 ссылки на источники из листа «Источники». | G26: нет
A27: 8 | B27: Подготовить одну страницу для показа и один конкретный вопрос аудитории («какой крючок открыли бы?»). | G27: нет
A28: 9 | B28: Подготовить ответы на ожидаемые возражения: спорные числа, предания, «это ИИ». | G28: нет
A29: 10 | B29: После вычитки RU/PT свериться, что факты совпадают во всех трёх языках. | G29: нет
A30: 11 | B30: Поправить spec §7 и схему Zod под новые лимиты (история 40–90, подробнее до 250 слов) и под три языка. | G30: нет

Sheet Карточки
A1: id | B1: Эпоха | C1: Уровень | D1: Год | E1: Название (RU, для себя) | F1: Нить 1 | G1: Нить 2 | H1: Важность 1–3 | I1: Метка | J1: Возраст | K1: Тяжёлая тема | L1: Статус работы | M1: Источников (найдено) | N1: Проверка | O1: Связанные id (через запятую) | P1: Интерактив: тип | Q1: Интерактив: данные (JSON) | R1: Рецензент | S1: Дата рецензии | T1: Заметки / ⚠ | U1: служ.: строка в Тексты | V1: служ.: строка в Места | W1: служ.: проблемы
A2: cantino-1502 | B2: avis-e-descobrimentos | C2: story | D2: 1502 | E2: Карта Кантино: шпион пришёл за лошадьми | F2: mar | H2: 1 | I2: documented | J2: all | K2: нет | L2: черновик | M2: =IF($A2="","",COUNTIFS(Источники!$A$2:$A$200,$A2,Источники!$G$2:$G$200,"нашли")) -> 8 | N2: =IF($A2="","",IF($W2="","OK",$W2)) -> координаты не проверены; | T2: Источники расходятся, когда карту нашли в лавке (Wikipedia: в 1859, NatGeo: через несколько лет): в тексте года находки нет. Копия в Museu de Marinha: проверить, выставлена ли. Адрес и координаты музея проверить. Картинку (Commons) найти и проверить лицензию. [16.10.2026] Кандидат на картинку записан в листе «Картинки» (файл ещё не скачан). Вид и кадрирование не проверялись. [16.10.2026] Правки владельца: в историю добавлено, как карта повлияла (копия в Генуе, затем карта Вальдземюллера 1507). «Подробнее» расширено и разбито на 4 абзаца. О судьбе самого Кантино после 1502 года надёжных данных не нашёл. | U2: =IF($A2="",0,IFERROR(MATCH($A2,Тексты!$A$1:$A$61,0),0)) -> 2 | V2: =IF($A2="",0,IFERROR(MATCH($A2,Места!$A$1:$A$61,0),0)) -> 2 | W2: =IF($A2="","",IF(COUNTIF($A$2:$A$61,$A2)>1,"дубль id; ","")&IF($B2="","нет эпохи; ","")&IF($C2="","нет уровня; ","")&IF($D2="","нет года; ","")&IF($F2="","нет нити; ","")&IF($H2="","нет важности; ","")&IF($I2="","нет метки; ","")&IF($J2="","нет возраста; ","")&IF($K2="","не указана тяжёлая тема; ","")&IF($M2<IF($C2="frame",2,1),"источников "&$M2&" из "&IF($C2="frame",2,1)&"; ","")&IF($U2=0,"нет строки в «Тексты»; ",IF(INDEX(Тексты!$C$1:$C$61,$U2)=0,"нет крючок EN; ",IF(OR(INDEX(Тексты!$C$1:$C$61,$U2)<1,INDEX(Тексты!$C$1:$C$61,$U2)>12),"крючок EN "&INDEX(Тексты!$C$1:$C$61,$U2)&" сл. (нужно 1–12); ",""))&IF(INDEX(Тексты!$E$1:$E$61,$U2)=0,"нет крючок PT; ",IF(OR(INDEX(Тексты!$E$1:$E$61,$U2)<1,INDEX(Тексты!$E$1:$E$61,$U2)>12),"крючок PT "&INDEX(Тексты!$E$1:$E$61,$U2)&" сл. (нужно 1–12); ",""))&IF(INDEX(Тексты!$O$1:$O$61,$U2)=0,"нет крючок RU; ",IF(OR(INDEX(Тексты!$O$1:$O$61,$U2)<1,INDEX(Тексты!$O$1:$O$61,$U2)>12),"крючок RU "&INDEX(Тексты!$O$1:$O$61,$U2)&" сл. (нужно 1–12); ",""))&IF(INDEX(Тексты!$G$1:$G$61,$U2)=0,"нет история EN; ",IF(OR(INDEX(Тексты!$G$1:$G$61,$U2)<40,INDEX(Тексты!$G$1:$G$61,$U2)>90),"история EN "&INDEX(Тексты!$G$1:$G$61,$U2)&" сл. (нужно 40–90); ",""))&IF(INDEX(Тексты!$I$1:$I$61,$U2)=0,"нет история PT; ",IF(OR(INDEX(Тексты!$I$1:$I$61,$U2)<40,INDEX(Тексты!$I$1:$I$61,$U2)>90),"история PT "&INDEX(Тексты!$I$1:$I$61,$U2)&" сл. (нужно 40–90); ",""))&IF(INDEX(Тексты!$Q$1:$Q$61,$U2)=0,"нет история RU; ",IF(OR(INDEX(Тексты!$Q$1:$Q$61,$U2)<40,INDEX(Тексты!$Q$1:$Q$61,$U2)>90),"история RU "&INDEX(Тексты!$Q$1:$Q$61,$U2)&" сл. (нужно 40–90); ",""))&IF(INDEX(Тексты!$K$1:$K$61,$U2)=0,"нет подробнее EN; ",IF(OR(INDEX(Тексты!$K$1:$K$61,$U2)<1,INDEX(Тексты!$K$1:$K$61,$U2)>250),"подробнее EN "&INDEX(Тексты!$K$1:$K$61,$U2)&" сл. (нужно 1–250); ",""))&IF(INDEX(Тексты!$M$1:$M$61,$U2)=0,"нет подробнее PT; ",IF(OR(INDEX(Тексты!$M$1:$M$61,$U2)<1,INDEX(Тексты!$M$1:$M$61,$U2)>250),"подробнее PT "&INDEX(Тексты!$M$1:$M$61,$U2)&" сл. (нужно 1–250); ",""))&IF(INDEX(Тексты!$S$1:$S$61,$U2)=0,"нет подробнее RU; ",IF(OR(INDEX(Тексты!$S$1:$S$61,$U2)<1,INDEX(Тексты!$S$1:$S$61,$U2)>250),"подробнее RU "&INDEX(Тексты!$S$1:$S$61,$U2)&" сл. (нужно 1–250); ","")))&IF($V2=0,"нет строки в «Места»; ",IF(OR(INDEX(Места!$B$1:$B$61,$V2)="",INDEX(Места!$C$1:$C$61,$V2)="",INDEX(Места!$Q$1:$Q$61,$V2)=""),"нет названия EN/PT/RU; ","")&IF(OR(INDEX(Места!$D$1:$D$61,$V2)="",INDEX(Места!$E$1:$E$61,$V2)="",INDEX(Места!$R$1:$R$61,$V2)=""),"нет slug EN/PT/RU; ","")&IF(INDEX(Места!$K$1:$K$61,$V2)="","нет моста в сегодня; ","")&IF(OR(INDEX(Места!$O$1:$O$61,$V2)="",INDEX(Места!$O$1:$O$61,$V2)="TODO"),"нет сайта моста; ","")&IF(INDEX(Места!$P$1:$P$61,$V2)<>"да","координаты не проверены; ",""))&IF(AND($L2="готово",OR($R2="",$S2="")),"нет рецензента/даты; ","")) -> координаты не проверены;
A3: rinoceronte-1515 | B3: avis-e-descobrimentos | C3: story | D3: 1515 | E3: Носорог и слон | F3: natureza | H3: 1 | I3: documented | J3: all | K3: нет | L3: черновик | M3: =IF($A3="","",COUNTIFS(Источники!$A$2:$A$200,$A3,Источники!$G$2:$G$200,"нашли")) -> 8 | N3: =IF($A3="","",IF($W3="","OK",$W3)) -> нет сайта моста; координаты не проверены; | T3: Метка documented, а не «Предание» как в design: решает историк. Адрес, сайт и координаты Торре-де-Белен проверить. [16.10.2026] Кандидат на картинку записан в листе «Картинки» (файл ещё не скачан). Вид и кадрирование не проверялись. [16.10.2026] Правки владельца: «Подробнее» разбито на 4 абзаца. Про чучело: версии расходятся, следов сохранившегося нет. | U3: =IF($A3="",0,IFERROR(MATCH($A3,Тексты!$A$1:$A$61,0),0)) -> 3 | V3: =IF($A3="",0,IFERROR(MATCH($A3,Места!$A$1:$A$61,0),0)) -> 3 | W3: =IF($A3="","",IF(COUNTIF($A$2:$A$61,$A3)>1,"дубль id; ","")&IF($B3="","нет эпохи; ","")&IF($C3="","нет уровня; ","")&IF($D3="","нет года; ","")&IF($F3="","нет нити; ","")&IF($H3="","нет важности; ","")&IF($I3="","нет метки; ","")&IF($J3="","нет возраста; ","")&IF($K3="","не указана тяжёлая тема; ","")&IF($M3<IF($C3="frame",2,1),"источников "&$M3&" из "&IF($C3="frame",2,1)&"; ","")&IF($U3=0,"нет строки в «Тексты»; ",IF(INDEX(Тексты!$C$1:$C$61,$U3)=0,"нет крючок EN; ",IF(OR(INDEX(Тексты!$C$1:$C$61,$U3)<1,INDEX(Тексты!$C$1:$C$61,$U3)>12),"крючок EN "&INDEX(Тексты!$C$1:$C$61,$U3)&" сл. (нужно 1–12); ",""))&IF(INDEX(Тексты!$E$1:$E$61,$U3)=0,"нет крючок PT; ",IF(OR(INDEX(Тексты!$E$1:$E$61,$U3)<1,INDEX(Тексты!$E$1:$E$61,$U3)>12),"крючок PT "&INDEX(Тексты!$E$1:$E$61,$U3)&" сл. (нужно 1–12); ",""))&IF(INDEX(Тексты!$O$1:$O$61,$U3)=0,"нет крючок RU; ",IF(OR(INDEX(Тексты!$O$1:$O$61,$U3)<1,INDEX(Тексты!$O$1:$O$61,$U3)>12),"крючок RU "&INDEX(Тексты!$O$1:$O$61,$U3)&" сл. (нужно 1–12); ",""))&IF(INDEX(Тексты!$G$1:$G$61,$U3)=0,"нет история EN; ",IF(OR(INDEX(Тексты!$G$1:$G$61,$U3)<40,INDEX(Тексты!$G$1:$G$61,$U3)>90),"история EN "&INDEX(Тексты!$G$1:$G$61,$U3)&" сл. (нужно 40–90); ",""))&IF(INDEX(Тексты!$I$1:$I$61,$U3)=0,"нет история PT; ",IF(OR(INDEX(Тексты!$I$1:$I$61,$U3)<40,INDEX(Тексты!$I$1:$I$61,$U3)>90),"история PT "&INDEX(Тексты!$I$1:$I$61,$U3)&" сл. (нужно 40–90); ",""))&IF(INDEX(Тексты!$Q$1:$Q$61,$U3)=0,"нет история RU; ",IF(OR(INDEX(Тексты!$Q$1:$Q$61,$U3)<40,INDEX(Тексты!$Q$1:$Q$61,$U3)>90),"история RU "&INDEX(Тексты!$Q$1:$Q$61,$U3)&" сл. (нужно 40–90); ",""))&IF(INDEX(Тексты!$K$1:$K$61,$U3)=0,"нет подробнее EN; ",IF(OR(INDEX(Тексты!$K$1:$K$61,$U3)<1,INDEX(Тексты!$K$1:$K$61,$U3)>250),"подробнее EN "&INDEX(Тексты!$K$1:$K$61,$U3)&" сл. (нужно 1–250); ",""))&IF(INDEX(Тексты!$M$1:$M$61,$U3)=0,"нет подробнее PT; ",IF(OR(INDEX(Тексты!$M$1:$M$61,$U3)<1,INDEX(Тексты!$M$1:$M$61,$U3)>250),"подробнее PT "&INDEX(Тексты!$M$1:$M$61,$U3)&" сл. (нужно 1–250); ",""))&IF(INDEX(Тексты!$S$1:$S$61,$U3)=0,"нет подробнее RU; ",IF(OR(INDEX(Тексты!$S$1:$S$61,$U3)<1,INDEX(Тексты!$S$1:$S$61,$U3)>250),"подробнее RU "&INDEX(Тексты!$S$1:$S$61,$U3)&" сл. (нужно 1–250); ","")))&IF($V3=0,"нет строки в «Места»; ",IF(OR(INDEX(Места!$B$1:$B$61,$V3)="",INDEX(Места!$C$1:$C$61,$V3)="",INDEX(Места!$Q$1:$Q$61,$V3)=""),"нет названия EN/PT/RU; ","")&IF(OR(INDEX(Места!$D$1:$D$61,$V3)="",INDEX(Места!$E$1:$E$61,$V3)="",INDEX(Места!$R$1:$R$61,$V3)=""),"нет slug EN/PT/RU; ","")&IF(INDEX(Места!$K$1:$K$61,$V3)="","нет моста в сегодня; ","")&IF(OR(INDEX(Места!$O$1:$O$61,$V3)="",INDEX(Места!$O$1:$O$61,$V3)="TODO"),"нет сайта моста; ","")&IF(INDEX(Места!$P$1:$P$61,$V3)<>"да","координаты не проверены; ",""))&IF(AND($L3="готово",OR($R3="",$S3="")),"нет рецензента/даты; ","")) -> нет сайта моста; координаты не проверены;
A4: tripeiros-1415 | B4: avis-e-descobrimentos | C4: story | D4: 1415 | E4: Tripeiros: город отдал мясо, оставил потроха | F4: comida-e-vinho | G4: gente-como-nos | H4: 1 | I4: legend | J4: all | K4: нет | L4: черновик | M4: =IF($A4="","",COUNTIFS(Источники!$A$2:$A$200,$A4,Источники!$G$2:$G$200,"нашли")) -> 5 | N4: =IF($A4="","",IF($W4="","OK",$W4)) -> координаты не проверены; | T4: Предание: у Зурары не нашли, современной хроники с этим сюжетом нет. Версии расходятся (в одной прозвище старше на 30 лет). Мост: памятник Лагоа Энрикеша 1960 г., официального названия, адреса и сайта нет: найти на сайте муниципалитета Порту. Запасной мост: вокзал Сан-Бенту (азулежу Жорже Колашу про Сеуту). Вторая нить «Люди как мы» на усмотрение владельца. [16.10.2026] Картинка v2 (азулежу, ИИ): мясо теперь читается, средневековая стена и порт ✓. ⚠ Дома с фахверком похожи на северную Европу, не на гранитный Порту; для превью использована обрезка 1200×630. Лицензия не проверена. | U4: =IF($A4="",0,IFERROR(MATCH($A4,Тексты!$A$1:$A$61,0),0)) -> 4 | V4: =IF($A4="",0,IFERROR(MATCH($A4,Места!$A$1:$A$61,0),0)) -> 4 | W4: =IF($A4="","",IF(COUNTIF($A$2:$A$61,$A4)>1,"дубль id; ","")&IF($B4="","нет эпохи; ","")&IF($C4="","нет уровня; ","")&IF($D4="","нет года; ","")&IF($F4="","нет нити; ","")&IF($H4="","нет важности; ","")&IF($I4="","нет метки; ","")&IF($J4="","нет возраста; ","")&IF($K4="","не указана тяжёлая тема; ","")&IF($M4<IF($C4="frame",2,1),"источников "&$M4&" из "&IF($C4="frame",2,1)&"; ","")&IF($U4=0,"нет строки в «Тексты»; ",IF(INDEX(Тексты!$C$1:$C$61,$U4)=0,"нет крючок EN; ",IF(OR(INDEX(Тексты!$C$1:$C$61,$U4)<1,INDEX(Тексты!$C$1:$C$61,$U4)>12),"крючок EN "&INDEX(Тексты!$C$1:$C$61,$U4)&" сл. (нужно 1–12); ",""))&IF(INDEX(Тексты!$E$1:$E$61,$U4)=0,"нет крючок PT; ",IF(OR(INDEX(Тексты!$E$1:$E$61,$U4)<1,INDEX(Тексты!$E$1:$E$61,$U4)>12),"крючок PT "&INDEX(Тексты!$E$1:$E$61,$U4)&" сл. (нужно 1–12); ",""))&IF(INDEX(Тексты!$O$1:$O$61,$U4)=0,"нет крючок RU; ",IF(OR(INDEX(Тексты!$O$1:$O$61,$U4)<1,INDEX(Тексты!$O$1:$O$61,$U4)>12),"крючок RU "&INDEX(Тексты!$O$1:$O$61,$U4)&" сл. (нужно 1–12); ",""))&IF(INDEX(Тексты!$G$1:$G$61,$U4)=0,"нет история EN; ",IF(OR(INDEX(Тексты!$G$1:$G$61,$U4)<40,INDEX(Тексты!$G$1:$G$61,$U4)>90),"история EN "&INDEX(Тексты!$G$1:$G$61,$U4)&" сл. (нужно 40–90); ",""))&IF(INDEX(Тексты!$I$1:$I$61,$U4)=0,"нет история PT; ",IF(OR(INDEX(Тексты!$I$1:$I$61,$U4)<40,INDEX(Тексты!$I$1:$I$61,$U4)>90),"история PT "&INDEX(Тексты!$I$1:$I$61,$U4)&" сл. (нужно 40–90); ",""))&IF(INDEX(Тексты!$Q$1:$Q$61,$U4)=0,"нет история RU; ",IF(OR(INDEX(Тексты!$Q$1:$Q$61,$U4)<40,INDEX(Тексты!$Q$1:$Q$61,$U4)>90),"история RU "&INDEX(Тексты!$Q$1:$Q$61,$U4)&" сл. (нужно 40–90); ",""))&IF(INDEX(Тексты!$K$1:$K$61,$U4)=0,"нет подробнее EN; ",IF(OR(INDEX(Тексты!$K$1:$K$61,$U4)<1,INDEX(Тексты!$K$1:$K$61,$U4)>250),"подробнее EN "&INDEX(Тексты!$K$1:$K$61,$U4)&" сл. (нужно 1–250); ",""))&IF(INDEX(Тексты!$M$1:$M$61,$U4)=0,"нет подробнее PT; ",IF(OR(INDEX(Тексты!$M$1:$M$61,$U4)<1,INDEX(Тексты!$M$1:$M$61,$U4)>250),"подробнее PT "&INDEX(Тексты!$M$1:$M$61,$U4)&" сл. (нужно 1–250); ",""))&IF(INDEX(Тексты!$S$1:$S$61,$U4)=0,"нет подробнее RU; ",IF(OR(INDEX(Тексты!$S$1:$S$61,$U4)<1,INDEX(Тексты!$S$1:$S$61,$U4)>250),"подробнее RU "&INDEX(Тексты!$S$1:$S$61,$U4)&" сл. (нужно 1–250); ","")))&IF($V4=0,"нет строки в «Места»; ",IF(OR(INDEX(Места!$B$1:$B$61,$V4)="",INDEX(Места!$C$1:$C$61,$V4)="",INDEX(Места!$Q$1:$Q$61,$V4)=""),"нет названия EN/PT/RU; ","")&IF(OR(INDEX(Места!$D$1:$D$61,$V4)="",INDEX(Места!$E$1:$E$61,$V4)="",INDEX(Места!$R$1:$R$61,$V4)=""),"нет slug EN/PT/RU; ","")&IF(INDEX(Места!$K$1:$K$61,$V4)="","нет моста в сегодня; ","")&IF(OR(INDEX(Места!$O$1:$O$61,$V4)="",INDEX(Места!$O$1:$O$61,$V4)="TODO"),"нет сайта моста; ","")&IF(INDEX(Места!$P$1:$P$61,$V4)<>"да","координаты не проверены; ",""))&IF(AND($L4="готово",OR($R4="",$S4="")),"нет рецензента/даты; ","")) -> координаты не проверены;
A5: guerra-laranjas-1801 | B5: pombal-e-terramoto | C5: frame | D5: 1801 | E5: Апельсиновая война: Годой теряет Элваш, Португалия теряет Оливенсу | F5: poder-e-revolta | H5: 2 | I5: documented | J5: all | K5: нет | L5: черновик | M5: =IF($A5="","",COUNTIFS(Источники!$A$2:$A$200,$A5,Источники!$G$2:$G$200,"нашли")) -> 8 | N5: =IF($A5="","",IF($W5="","OK",$W5)) -> нет сайта моста; координаты не проверены; | O5: torres-vedras-1810 | T5: Анекдот про ветку апельсина (в PT-источниках «ramo de flores de laranjeira», в документе «ветки апельсина») подан как предание, метка карточки documented относится к войне и договору. Даты расходятся: 20 мая–6 июня или 9 июня; в тексте только «май 1801» и подпись договора 6 июня. Вена 1815 / ратификация Испанией 7 мая 1817: Observador и MNE, лучше взять сам Заключительный акт (ст. 105). Мост: Эльваш (ЮНЕСКО), точка посещения и адрес не выбраны; Оливенса как второй мост. Крепость Santa Luzia из документа не проверена. Координаты приблизительные. [Перепроверка 16.10.2026] Мост в Эльваше не выбран: Forte de Santa Luzia не проверен, в этом раунде не искал. [16.10.2026] Картинка (азулежу, ИИ): сцена с веткой апельсина читается. ⚠ Крепость на холме нарисована как средневековый замок, а не звёздчатый форт Эльваша; в превью она обрезана. Подпись говорит, что это предание. Лицензия не проверена. [16.10.2026] Правки владельца: новый хук; в истории объяснено, почему апельсиновая ветка; «Подробнее» расширено. | U5: =IF($A5="",0,IFERROR(MATCH($A5,Тексты!$A$1:$A$61,0),0)) -> 5 | V5: =IF($A5="",0,IFERROR(MATCH($A5,Места!$A$1:$A$61,0),0)) -> 5 | W5: =IF($A5="","",IF(COUNTIF($A$2:$A$61,$A5)>1,"дубль id; ","")&IF($B5="","нет эпохи; ","")&IF($C5="","нет уровня; ","")&IF($D5="","нет года; ","")&IF($F5="","нет нити; ","")&IF($H5="","нет важности; ","")&IF($I5="","нет метки; ","")&IF($J5="","нет возраста; ","")&IF($K5="","не указана тяжёлая тема; ","")&IF($M5<IF($C5="frame",2,1),"источников "&$M5&" из "&IF($C5="frame",2,1)&"; ","")&IF($U5=0,"нет строки в «Тексты»; ",IF(INDEX(Тексты!$C$1:$C$61,$U5)=0,"нет крючок EN; ",IF(OR(INDEX(Тексты!$C$1:$C$61,$U5)<1,INDEX(Тексты!$C$1:$C$61,$U5)>12),"крючок EN "&INDEX(Тексты!$C$1:$C$61,$U5)&" сл. (нужно 1–12); ",""))&IF(INDEX(Тексты!$E$1:$E$61,$U5)=0,"нет крючок PT; ",IF(OR(INDEX(Тексты!$E$1:$E$61,$U5)<1,INDEX(Тексты!$E$1:$E$61,$U5)>12),"крючок PT "&INDEX(Тексты!$E$1:$E$61,$U5)&" сл. (нужно 1–12); ",""))&IF(INDEX(Тексты!$O$1:$O$61,$U5)=0,"нет крючок RU; ",IF(OR(INDEX(Тексты!$O$1:$O$61,$U5)<1,INDEX(Тексты!$O$1:$O$61,$U5)>12),"крючок RU "&INDEX(Тексты!$O$1:$O$61,$U5)&" сл. (нужно 1–12); ",""))&IF(INDEX(Тексты!$G$1:$G$61,$U5)=0,"нет история EN; ",IF(OR(INDEX(Тексты!$G$1:$G$61,$U5)<40,INDEX(Тексты!$G$1:$G$61,$U5)>90),"история EN "&INDEX(Тексты!$G$1:$G$61,$U5)&" сл. (нужно 40–90); ",""))&IF(INDEX(Тексты!$I$1:$I$61,$U5)=0,"нет история PT; ",IF(OR(INDEX(Тексты!$I$1:$I$61,$U5)<40,INDEX(Тексты!$I$1:$I$61,$U5)>90),"история PT "&INDEX(Тексты!$I$1:$I$61,$U5)&" сл. (нужно 40–90); ",""))&IF(INDEX(Тексты!$Q$1:$Q$61,$U5)=0,"нет история RU; ",IF(OR(INDEX(Тексты!$Q$1:$Q$61,$U5)<40,INDEX(Тексты!$Q$1:$Q$61,$U5)>90),"история RU "&INDEX(Тексты!$Q$1:$Q$61,$U5)&" сл. (нужно 40–90); ",""))&IF(INDEX(Тексты!$K$1:$K$61,$U5)=0,"нет подробнее EN; ",IF(OR(INDEX(Тексты!$K$1:$K$61,$U5)<1,INDEX(Тексты!$K$1:$K$61,$U5)>250),"подробнее EN "&INDEX(Тексты!$K$1:$K$61,$U5)&" сл. (нужно 1–250); ",""))&IF(INDEX(Тексты!$M$1:$M$61,$U5)=0,"нет подробнее PT; ",IF(OR(INDEX(Тексты!$M$1:$M$61,$U5)<1,INDEX(Тексты!$M$1:$M$61,$U5)>250),"подробнее PT "&INDEX(Тексты!$M$1:$M$61,$U5)&" сл. (нужно 1–250); ",""))&IF(INDEX(Тексты!$S$1:$S$61,$U5)=0,"нет подробнее RU; ",IF(OR(INDEX(Тексты!$S$1:$S$61,$U5)<1,INDEX(Тексты!$S$1:$S$61,$U5)>250),"подробнее RU "&INDEX(Тексты!$S$1:$S$61,$U5)&" сл. (нужно 1–250); ","")))&IF($V5=0,"нет строки в «Места»; ",IF(OR(INDEX(Места!$B$1:$B$61,$V5)="",INDEX(Места!$C$1:$C$61,$V5)="",INDEX(Места!$Q$1:$Q$61,$V5)=""),"нет названия EN/PT/RU; ","")&IF(OR(INDEX(Места!$D$1:$D$61,$V5)="",INDEX(Места!$E$1:$E$61,$V5)="",INDEX(Места!$R$1:$R$61,$V5)=""),"нет slug EN/PT/RU; ","")&IF(INDEX(Места!$K$1:$K$61,$V5)="","нет моста в сегодня; ","")&IF(OR(INDEX(Места!$O$1:$O$61,$V5)="",INDEX(Места!$O$1:$O$61,$V5)="TODO"),"нет сайта моста; ","")&IF(INDEX(Места!$P$1:$P$61,$V5)<>"да","координаты не проверены; ",""))&IF(AND($L5="готово",OR($R5="",$S5="")),"нет рецензента/даты; ","")) -> нет сайта моста; координаты не проверены;
A6: casa-da-neve-1782 | B6: pombal-e-terramoto | C6: story | D6: 1782 | E6: Casa da Neve: кафе, которое открыл «снежный мастер» короля | F6: comida-e-vinho | G6: gente-como-nos | H6: 1 | I6: documented | J6: all | K6: нет | L6: черновик | M6: =IF($A6="","",COUNTIFS(Источники!$A$2:$A$200,$A6,Источники!$G$2:$G$200,"нашли")) -> 14 | N6: =IF($A6="","",IF($W6="","OK",$W6)) -> координаты не проверены; | O6: terramoto-1755 | T6: Источники расходятся: день открытия (2 или 7 января 1782), год, когда кафе получило имя Martinho (1829 или 1845). В тексте дня нет, в «Подробнее» оба варианта. Откуда возили снег (Эштрела, Монтежунту?) источники не говорят: в текст не включено. Основатель Julião Pereira de Castro, neveiro-mor da Casa Real: одна газетная статья (CM), нужен второй источник. «Площадь отстроена после 1755» взято из общих знаний, подтвердить. Вторая нить на усмотрение владельца. Официальный сайт кафе найти (пока страница «Lojas com História»). Координаты приблизительные. [Перепроверка 16.10.2026] Год основания в одном источнике 1778 (Ara), в остальных 1782. Источников стало 6. Мост: часы и название стола проверить на сайте кафе. [16.10.2026] Мост заполнен: Café Martinho da Arcada, Praça do Comércio 3 (в реестре города указан Rua da Prata 2/8). Часы расходятся: пн–сб 7–23 по реестру города, ежедневно 12–22 по Time Out; смотреть на martinhodaarcada.pt. Координат нет. Картинка: свободного файла не нашёл, можно снять самому. [16.10.2026] Правки владельца: «Подробнее» расширено (путь снега, монополия, «neve», ссора с Marrare). Год открытия 1778 или 1782 вынесен в историю и подпись года. | U6: =IF($A6="",0,IFERROR(MATCH($A6,Тексты!$A$1:$A$61,0),0)) -> 6 | V6: =IF($A6="",0,IFERROR(MATCH($A6,Места!$A$1:$A$61,0),0)) -> 6 | W6: =IF($A6="","",IF(COUNTIF($A$2:$A$61,$A6)>1,"дубль id; ","")&IF($B6="","нет эпохи; ","")&IF($C6="","нет уровня; ","")&IF($D6="","нет года; ","")&IF($F6="","нет нити; ","")&IF($H6="","нет важности; ","")&IF($I6="","нет метки; ","")&IF($J6="","нет возраста; ","")&IF($K6="","не указана тяжёлая тема; ","")&IF($M6<IF($C6="frame",2,1),"источников "&$M6&" из "&IF($C6="frame",2,1)&"; ","")&IF($U6=0,"нет строки в «Тексты»; ",IF(INDEX(Тексты!$C$1:$C$61,$U6)=0,"нет крючок EN; ",IF(OR(INDEX(Тексты!$C$1:$C$61,$U6)<1,INDEX(Тексты!$C$1:$C$61,$U6)>12),"крючок EN "&INDEX(Тексты!$C$1:$C$61,$U6)&" сл. (нужно 1–12); ",""))&IF(INDEX(Тексты!$E$1:$E$61,$U6)=0,"нет крючок PT; ",IF(OR(INDEX(Тексты!$E$1:$E$61,$U6)<1,INDEX(Тексты!$E$1:$E$61,$U6)>12),"крючок PT "&INDEX(Тексты!$E$1:$E$61,$U6)&" сл. (нужно 1–12); ",""))&IF(INDEX(Тексты!$O$1:$O$61,$U6)=0,"нет крючок RU; ",IF(OR(INDEX(Тексты!$O$1:$O$61,$U6)<1,INDEX(Тексты!$O$1:$O$61,$U6)>12),"крючок RU "&INDEX(Тексты!$O$1:$O$61,$U6)&" сл. (нужно 1–12); ",""))&IF(INDEX(Тексты!$G$1:$G$61,$U6)=0,"нет история EN; ",IF(OR(INDEX(Тексты!$G$1:$G$61,$U6)<40,INDEX(Тексты!$G$1:$G$61,$U6)>90),"история EN "&INDEX(Тексты!$G$1:$G$61,$U6)&" сл. (нужно 40–90); ",""))&IF(INDEX(Тексты!$I$1:$I$61,$U6)=0,"нет история PT; ",IF(OR(INDEX(Тексты!$I$1:$I$61,$U6)<40,INDEX(Тексты!$I$1:$I$61,$U6)>90),"история PT "&INDEX(Тексты!$I$1:$I$61,$U6)&" сл. (нужно 40–90); ",""))&IF(INDEX(Тексты!$Q$1:$Q$61,$U6)=0,"нет история RU; ",IF(OR(INDEX(Тексты!$Q$1:$Q$61,$U6)<40,INDEX(Тексты!$Q$1:$Q$61,$U6)>90),"история RU "&INDEX(Тексты!$Q$1:$Q$61,$U6)&" сл. (нужно 40–90); ",""))&IF(INDEX(Тексты!$K$1:$K$61,$U6)=0,"нет подробнее EN; ",IF(OR(INDEX(Тексты!$K$1:$K$61,$U6)<1,INDEX(Тексты!$K$1:$K$61,$U6)>250),"подробнее EN "&INDEX(Тексты!$K$1:$K$61,$U6)&" сл. (нужно 1–250); ",""))&IF(INDEX(Тексты!$M$1:$M$61,$U6)=0,"нет подробнее PT; ",IF(OR(INDEX(Тексты!$M$1:$M$61,$U6)<1,INDEX(Тексты!$M$1:$M$61,$U6)>250),"подробнее PT "&INDEX(Тексты!$M$1:$M$61,$U6)&" сл. (нужно 1–250); ",""))&IF(INDEX(Тексты!$S$1:$S$61,$U6)=0,"нет подробнее RU; ",IF(OR(INDEX(Тексты!$S$1:$S$61,$U6)<1,INDEX(Тексты!$S$1:$S$61,$U6)>250),"подробнее RU "&INDEX(Тексты!$S$1:$S$61,$U6)&" сл. (нужно 1–250); ","")))&IF($V6=0,"нет строки в «Места»; ",IF(OR(INDEX(Места!$B$1:$B$61,$V6)="",INDEX(Места!$C$1:$C$61,$V6)="",INDEX(Места!$Q$1:$Q$61,$V6)=""),"нет названия EN/PT/RU; ","")&IF(OR(INDEX(Места!$D$1:$D$61,$V6)="",INDEX(Места!$E$1:$E$61,$V6)="",INDEX(Места!$R$1:$R$61,$V6)=""),"нет slug EN/PT/RU; ","")&IF(INDEX(Места!$K$1:$K$61,$V6)="","нет моста в сегодня; ","")&IF(OR(INDEX(Места!$O$1:$O$61,$V6)="",INDEX(Места!$O$1:$O$61,$V6)="TODO"),"нет сайта моста; ","")&IF(INDEX(Места!$P$1:$P$61,$V6)<>"да","координаты не проверены; ",""))&IF(AND($L6="готово",OR($R6="",$S6="")),"нет рецензента/даты; ","")) -> координаты не проверены;
A7: douro-1756 | B7: pombal-e-terramoto | C7: story | D7: 1756 | E7: Камни, которыми огородили портвейн | F7: comida-e-vinho | G7: poder-e-revolta | H7: 1 | I7: documented | J7: all | K7: нет | L7: черновик | M7: =IF($A7="","",COUNTIFS(Источники!$A$2:$A$200,$A7,Источники!$G$2:$G$200,"нашли")) -> 4 | N7: =IF($A7="","",IF($W7="","OK",$W7)) -> координаты не проверены; | O7: motim-companhia-1757 | T7: [16.10.2026] Новая карточка: выделена из Motim по замечанию владельца (основание Компании и демаркация отдельно от бунта). Факты по Taylor's, Wine Anorak, UP; «бузина» подана без подробностей про подделку цвета. Картинка: фото marco pombalino на Commons не искал. | U7: =IF($A7="",0,IFERROR(MATCH($A7,Тексты!$A$1:$A$61,0),0)) -> 7 | V7: =IF($A7="",0,IFERROR(MATCH($A7,Места!$A$1:$A$61,0),0)) -> 7 | W7: =IF($A7="","",IF(COUNTIF($A$2:$A$61,$A7)>1,"дубль id; ","")&IF($B7="","нет эпохи; ","")&IF($C7="","нет уровня; ","")&IF($D7="","нет года; ","")&IF($F7="","нет нити; ","")&IF($H7="","нет важности; ","")&IF($I7="","нет метки; ","")&IF($J7="","нет возраста; ","")&IF($K7="","не указана тяжёлая тема; ","")&IF($M7<IF($C7="frame",2,1),"источников "&$M7&" из "&IF($C7="frame",2,1)&"; ","")&IF($U7=0,"нет строки в «Тексты»; ",IF(INDEX(Тексты!$C$1:$C$61,$U7)=0,"нет крючок EN; ",IF(OR(INDEX(Тексты!$C$1:$C$61,$U7)<1,INDEX(Тексты!$C$1:$C$61,$U7)>12),"крючок EN "&INDEX(Тексты!$C$1:$C$61,$U7)&" сл. (нужно 1–12); ",""))&IF(INDEX(Тексты!$E$1:$E$61,$U7)=0,"нет крючок PT; ",IF(OR(INDEX(Тексты!$E$1:$E$61,$U7)<1,INDEX(Тексты!$E$1:$E$61,$U7)>12),"крючок PT "&INDEX(Тексты!$E$1:$E$61,$U7)&" сл. (нужно 1–12); ",""))&IF(INDEX(Тексты!$O$1:$O$61,$U7)=0,"нет крючок RU; ",IF(OR(INDEX(Тексты!$O$1:$O$61,$U7)<1,INDEX(Тексты!$O$1:$O$61,$U7)>12),"крючок RU "&INDEX(Тексты!$O$1:$O$61,$U7)&" сл. (нужно 1–12); ",""))&IF(INDEX(Тексты!$G$1:$G$61,$U7)=0,"нет история EN; ",IF(OR(INDEX(Тексты!$G$1:$G$61,$U7)<40,INDEX(Тексты!$G$1:$G$61,$U7)>90),"история EN "&INDEX(Тексты!$G$1:$G$61,$U7)&" сл. (нужно 40–90); ",""))&IF(INDEX(Тексты!$I$1:$I$61,$U7)=0,"нет история PT; ",IF(OR(INDEX(Тексты!$I$1:$I$61,$U7)<40,INDEX(Тексты!$I$1:$I$61,$U7)>90),"история PT "&INDEX(Тексты!$I$1:$I$61,$U7)&" сл. (нужно 40–90); ",""))&IF(INDEX(Тексты!$Q$1:$Q$61,$U7)=0,"нет история RU; ",IF(OR(INDEX(Тексты!$Q$1:$Q$61,$U7)<40,INDEX(Тексты!$Q$1:$Q$61,$U7)>90),"история RU "&INDEX(Тексты!$Q$1:$Q$61,$U7)&" сл. (нужно 40–90); ",""))&IF(INDEX(Тексты!$K$1:$K$61,$U7)=0,"нет подробнее EN; ",IF(OR(INDEX(Тексты!$K$1:$K$61,$U7)<1,INDEX(Тексты!$K$1:$K$61,$U7)>250),"подробнее EN "&INDEX(Тексты!$K$1:$K$61,$U7)&" сл. (нужно 1–250); ",""))&IF(INDEX(Тексты!$M$1:$M$61,$U7)=0,"нет подробнее PT; ",IF(OR(INDEX(Тексты!$M$1:$M$61,$U7)<1,INDEX(Тексты!$M$1:$M$61,$U7)>250),"подробнее PT "&INDEX(Тексты!$M$1:$M$61,$U7)&" сл. (нужно 1–250); ",""))&IF(INDEX(Тексты!$S$1:$S$61,$U7)=0,"нет подробнее RU; ",IF(OR(INDEX(Тексты!$S$1:$S$61,$U7)<1,INDEX(Тексты!$S$1:$S$61,$U7)>250),"подробнее RU "&INDEX(Тексты!$S$1:$S$61,$U7)&" сл. (нужно 1–250); ","")))&IF($V7=0,"нет строки в «Места»; ",IF(OR(INDEX(Места!$B$1:$B$61,$V7)="",INDEX(Места!$C$1:$C$61,$V7)="",INDEX(Места!$Q$1:$Q$61,$V7)=""),"нет названия EN/PT/RU; ","")&IF(OR(INDEX(Места!$D$1:$D$61,$V7)="",INDEX(Места!$E$1:$E$61,$V7)="",INDEX(Места!$R$1:$R$61,$V7)=""),"нет slug EN/PT/RU; ","")&IF(INDEX(Места!$K$1:$K$61,$V7)="","нет моста в сегодня; ","")&IF(OR(INDEX(Места!$O$1:$O$61,$V7)="",INDEX(Места!$O$1:$O$61,$V7)="TODO"),"нет сайта моста; ","")&IF(INDEX(Места!$P$1:$P$61,$V7)<>"да","координаты не проверены; ",""))&IF(AND($L7="готово",OR($R7="",$S7="")),"нет рецензента/даты; ","")) -> координаты не проверены;
A8: elefantes-malaca-1511 | B8: avis-e-descobrimentos | C8: story | D8: 1511 | E8: День, когда слоны повернули назад (Малакка) | F8: natureza | H8: 1 | I8: documented | J8: 12 | K8: нет | L8: черновик | M8: =IF($A8="","",COUNTIFS(Источники!$A$2:$A$200,$A8,Источники!$G$2:$G$200,"нашли")) -> 10 | N8: =IF($A8="","",IF($W8="","OK",$W8)) -> нет сайта моста; координаты не проверены; | T8: Источники расходятся: число слонов (≈20 по одному, «стадо» по другому) и как упал султан. «Отравленные дротики» и «4-метровые пики» из списка Gemini не подтвердились: в тексте только «лэнс/копьё». Первоисточник (хроники, «Комментарии») не читан. Мост: Casa dos Bicos, построена сыном Албукерки Брасом: проверить координаты, часы работы (источники расходятся: пн–пт или пн–сб). [16.10.2026] Дата падения города (15 или 24 августа) и численность сил расходятся: см. заметку в «Тексты». Кандидат на картинку: рисунок «Malaca» из Lendas da Índia Гаспара Корреи (Torre do Tombo). [16.10.2026] Кандидат на картинку записан в листе «Картинки» (файл ещё не скачан). Вид и кадрирование не проверялись. [16.10.2026] Правки владельца: новый хук, история с цитатой Пиреша. Мост заменён на памятник Албукерки в Белеме (Casa dos Bicos осталась в тексте через сына Браша). Официальной страницы моста нет. | U8: =IF($A8="",0,IFERROR(MATCH($A8,Тексты!$A$1:$A$61,0),0)) -> 8 | V8: =IF($A8="",0,IFERROR(MATCH($A8,Места!$A$1:$A$61,0),0)) -> 8 | W8: =IF($A8="","",IF(COUNTIF($A$2:$A$61,$A8)>1,"дубль id; ","")&IF($B8="","нет эпохи; ","")&IF($C8="","нет уровня; ","")&IF($D8="","нет года; ","")&IF($F8="","нет нити; ","")&IF($H8="","нет важности; ","")&IF($I8="","нет метки; ","")&IF($J8="","нет возраста; ","")&IF($K8="","не указана тяжёлая тема; ","")&IF($M8<IF($C8="frame",2,1),"источников "&$M8&" из "&IF($C8="frame",2,1)&"; ","")&IF($U8=0,"нет строки в «Тексты»; ",IF(INDEX(Тексты!$C$1:$C$61,$U8)=0,"нет крючок EN; ",IF(OR(INDEX(Тексты!$C$1:$C$61,$U8)<1,INDEX(Тексты!$C$1:$C$61,$U8)>12),"крючок EN "&INDEX(Тексты!$C$1:$C$61,$U8)&" сл. (нужно 1–12); ",""))&IF(INDEX(Тексты!$E$1:$E$61,$U8)=0,"нет крючок PT; ",IF(OR(INDEX(Тексты!$E$1:$E$61,$U8)<1,INDEX(Тексты!$E$1:$E$61,$U8)>12),"крючок PT "&INDEX(Тексты!$E$1:$E$61,$U8)&" сл. (нужно 1–12); ",""))&IF(INDEX(Тексты!$O$1:$O$61,$U8)=0,"нет крючок RU; ",IF(OR(INDEX(Тексты!$O$1:$O$61,$U8)<1,INDEX(Тексты!$O$1:$O$61,$U8)>12),"крючок RU "&INDEX(Тексты!$O$1:$O$61,$U8)&" сл. (нужно 1–12); ",""))&IF(INDEX(Тексты!$G$1:$G$61,$U8)=0,"нет история EN; ",IF(OR(INDEX(Тексты!$G$1:$G$61,$U8)<40,INDEX(Тексты!$G$1:$G$61,$U8)>90),"история EN "&INDEX(Тексты!$G$1:$G$61,$U8)&" сл. (нужно 40–90); ",""))&IF(INDEX(Тексты!$I$1:$I$61,$U8)=0,"нет история PT; ",IF(OR(INDEX(Тексты!$I$1:$I$61,$U8)<40,INDEX(Тексты!$I$1:$I$61,$U8)>90),"история PT "&INDEX(Тексты!$I$1:$I$61,$U8)&" сл. (нужно 40–90); ",""))&IF(INDEX(Тексты!$Q$1:$Q$61,$U8)=0,"нет история RU; ",IF(OR(INDEX(Тексты!$Q$1:$Q$61,$U8)<40,INDEX(Тексты!$Q$1:$Q$61,$U8)>90),"история RU "&INDEX(Тексты!$Q$1:$Q$61,$U8)&" сл. (нужно 40–90); ",""))&IF(INDEX(Тексты!$K$1:$K$61,$U8)=0,"нет подробнее EN; ",IF(OR(INDEX(Тексты!$K$1:$K$61,$U8)<1,INDEX(Тексты!$K$1:$K$61,$U8)>250),"подробнее EN "&INDEX(Тексты!$K$1:$K$61,$U8)&" сл. (нужно 1–250); ",""))&IF(INDEX(Тексты!$M$1:$M$61,$U8)=0,"нет подробнее PT; ",IF(OR(INDEX(Тексты!$M$1:$M$61,$U8)<1,INDEX(Тексты!$M$1:$M$61,$U8)>250),"подробнее PT "&INDEX(Тексты!$M$1:$M$61,$U8)&" сл. (нужно 1–250); ",""))&IF(INDEX(Тексты!$S$1:$S$61,$U8)=0,"нет подробнее RU; ",IF(OR(INDEX(Тексты!$S$1:$S$61,$U8)<1,INDEX(Тексты!$S$1:$S$61,$U8)>250),"подробнее RU "&INDEX(Тексты!$S$1:$S$61,$U8)&" сл. (нужно 1–250); ","")))&IF($V8=0,"нет строки в «Места»; ",IF(OR(INDEX(Места!$B$1:$B$61,$V8)="",INDEX(Места!$C$1:$C$61,$V8)="",INDEX(Места!$Q$1:$Q$61,$V8)=""),"нет названия EN/PT/RU; ","")&IF(OR(INDEX(Места!$D$1:$D$61,$V8)="",INDEX(Места!$E$1:$E$61,$V8)="",INDEX(Места!$R$1:$R$61,$V8)=""),"нет slug EN/PT/RU; ","")&IF(INDEX(Места!$K$1:$K$61,$V8)="","нет моста в сегодня; ","")&IF(OR(INDEX(Места!$O$1:$O$61,$V8)="",INDEX(Места!$O$1:$O$61,$V8)="TODO"),"нет сайта моста; ","")&IF(INDEX(Места!$P$1:$P$61,$V8)<>"да","координаты не проверены; ",""))&IF(AND($L8="готово",OR($R8="",$S8="")),"нет рецензента/даты; ","")) -> нет сайта моста; координаты не проверены;
A9: torres-vedras-1810 | B9: pombal-e-terramoto | C9: frame | D9: 1810 | E9: Линии Торрес-Ведрас: Массена нашёл крепость, о которой не знал | F9: poder-e-revolta | G9: gente-como-nos | H9: 3 | I9: documented | J9: 12 | K9: да | L9: черновик | M9: =IF($A9="","",COUNTIFS(Источники!$A$2:$A$200,$A9,Источники!$G$2:$G$200,"нашли")) -> 7 | N9: =IF($A9="","",IF($W9="","OK",$W9)) -> координаты не проверены; | O9: legiao-portuguesa-1812, ponte-das-barcas-1809 | T9: Число фортов не вынесено в текст: источники расходятся (в документе 152, в справочниках «более 150»). «Тысячи рабочих» заменено на «Portuguese workers»: число не подтверждено. Число португальских мирных жертв (≈50 тыс. по Military Wiki) слабый источник: в «Подробнее» только «десятки тысяч» с оговоркой, нужен научный источник. Заданные в тексте 60 000 у Массены: Wikipedia (61 000), историки дают 60–65 тыс. Форт São Vicente и его часы работы не проверены. Координаты форта не заполнены. Вторая нить на усмотрение владельца. [Перепроверка 16.10.2026] Мост выбран: Центр интерпретации Линий в форте São Vicente (официальный сайт маршрута). Часы (10–13, 14–18, закрыт по понедельникам) и цена (2 €) смотрите на сайте при публикации. Координаты форта ещё не заполнены. [16.10.2026] Кандидат на картинку записан в листе «Картинки» (файл ещё не скачан). Вид и кадрирование не проверялись. [16.10.2026] Правки владельца: новый хук. | U9: =IF($A9="",0,IFERROR(MATCH($A9,Тексты!$A$1:$A$61,0),0)) -> 9 | V9: =IF($A9="",0,IFERROR(MATCH($A9,Места!$A$1:$A$61,0),0)) -> 9 | W9: =IF($A9="","",IF(COUNTIF($A$2:$A$61,$A9)>1,"дубль id; ","")&IF($B9="","нет эпохи; ","")&IF($C9="","нет уровня; ","")&IF($D9="","нет года; ","")&IF($F9="","нет нити; ","")&IF($H9="","нет важности; ","")&IF($I9="","нет метки; ","")&IF($J9="","нет возраста; ","")&IF($K9="","не указана тяжёлая тема; ","")&IF($M9<IF($C9="frame",2,1),"источников "&$M9&" из "&IF($C9="frame",2,1)&"; ","")&IF($U9=0,"нет строки в «Тексты»; ",IF(INDEX(Тексты!$C$1:$C$61,$U9)=0,"нет крючок EN; ",IF(OR(INDEX(Тексты!$C$1:$C$61,$U9)<1,INDEX(Тексты!$C$1:$C$61,$U9)>12),"крючок EN "&INDEX(Тексты!$C$1:$C$61,$U9)&" сл. (нужно 1–12); ",""))&IF(INDEX(Тексты!$E$1:$E$61,$U9)=0,"нет крючок PT; ",IF(OR(INDEX(Тексты!$E$1:$E$61,$U9)<1,INDEX(Тексты!$E$1:$E$61,$U9)>12),"крючок PT "&INDEX(Тексты!$E$1:$E$61,$U9)&" сл. (нужно 1–12); ",""))&IF(INDEX(Тексты!$O$1:$O$61,$U9)=0,"нет крючок RU; ",IF(OR(INDEX(Тексты!$O$1:$O$61,$U9)<1,INDEX(Тексты!$O$1:$O$61,$U9)>12),"крючок RU "&INDEX(Тексты!$O$1:$O$61,$U9)&" сл. (нужно 1–12); ",""))&IF(INDEX(Тексты!$G$1:$G$61,$U9)=0,"нет история EN; ",IF(OR(INDEX(Тексты!$G$1:$G$61,$U9)<40,INDEX(Тексты!$G$1:$G$61,$U9)>90),"история EN "&INDEX(Тексты!$G$1:$G$61,$U9)&" сл. (нужно 40–90); ",""))&IF(INDEX(Тексты!$I$1:$I$61,$U9)=0,"нет история PT; ",IF(OR(INDEX(Тексты!$I$1:$I$61,$U9)<40,INDEX(Тексты!$I$1:$I$61,$U9)>90),"история PT "&INDEX(Тексты!$I$1:$I$61,$U9)&" сл. (нужно 40–90); ",""))&IF(INDEX(Тексты!$Q$1:$Q$61,$U9)=0,"нет история RU; ",IF(OR(INDEX(Тексты!$Q$1:$Q$61,$U9)<40,INDEX(Тексты!$Q$1:$Q$61,$U9)>90),"история RU "&INDEX(Тексты!$Q$1:$Q$61,$U9)&" сл. (нужно 40–90); ",""))&IF(INDEX(Тексты!$K$1:$K$61,$U9)=0,"нет подробнее EN; ",IF(OR(INDEX(Тексты!$K$1:$K$61,$U9)<1,INDEX(Тексты!$K$1:$K$61,$U9)>250),"подробнее EN "&INDEX(Тексты!$K$1:$K$61,$U9)&" сл. (нужно 1–250); ",""))&IF(INDEX(Тексты!$M$1:$M$61,$U9)=0,"нет подробнее PT; ",IF(OR(INDEX(Тексты!$M$1:$M$61,$U9)<1,INDEX(Тексты!$M$1:$M$61,$U9)>250),"подробнее PT "&INDEX(Тексты!$M$1:$M$61,$U9)&" сл. (нужно 1–250); ",""))&IF(INDEX(Тексты!$S$1:$S$61,$U9)=0,"нет подробнее RU; ",IF(OR(INDEX(Тексты!$S$1:$S$61,$U9)<1,INDEX(Тексты!$S$1:$S$61,$U9)>250),"подробнее RU "&INDEX(Тексты!$S$1:$S$61,$U9)&" сл. (нужно 1–250); ","")))&IF($V9=0,"нет строки в «Места»; ",IF(OR(INDEX(Места!$B$1:$B$61,$V9)="",INDEX(Места!$C$1:$C$61,$V9)="",INDEX(Места!$Q$1:$Q$61,$V9)=""),"нет названия EN/PT/RU; ","")&IF(OR(INDEX(Места!$D$1:$D$61,$V9)="",INDEX(Места!$E$1:$E$61,$V9)="",INDEX(Места!$R$1:$R$61,$V9)=""),"нет slug EN/PT/RU; ","")&IF(INDEX(Места!$K$1:$K$61,$V9)="","нет моста в сегодня; ","")&IF(OR(INDEX(Места!$O$1:$O$61,$V9)="",INDEX(Места!$O$1:$O$61,$V9)="TODO"),"нет сайта моста; ","")&IF(INDEX(Места!$P$1:$P$61,$V9)<>"да","координаты не проверены; ",""))&IF(AND($L9="готово",OR($R9="",$S9="")),"нет рецензента/даты; ","")) -> координаты не проверены;
A10: aljubarrota-1385 | B10: avis-e-descobrimentos | C10: frame | D10: 1385 | E10: Алжубарроту | F10: poder-e-revolta | G10: gente-como-nos | H10: 3 | I10: documented | J10: 12 | K10: нет | L10: черновик | M10: =IF($A10="","",COUNTIFS(Источники!$A$2:$A$200,$A10,Источники!$G$2:$G$200,"нашли")) -> 9 | N10: =IF($A10="","",IF($W10="","OK",$W10)) -> координаты не проверены; | O10: terramoto-1755 | P10: army_dots | Q10: {"dot_value": 1000, "portuguese": {"low": 7000, "high": 7000}, "castilian": {"low": 18000, "high": 44000}, "castilian_in_combat": 10000, "caption": {"en": "By historians' estimates. Figures vary widely between sources.", "pt": "Segundo estimativas de historiadores. Os números variam muito entre fontes."}} | T10: Текст переписан (v3): совет не согласился, Нуну 25 лет, конец через Кармо. Цифра 18 000 из слабого источника. sensitive=нет и вторая нить: решения владельца. Лопеш про «час вечерни» взят из панно CIBA, сам текст хроники не читан. [16.10.2026] Хук и история смягчены: рвы и ямы известны по Froissart, у Лопеша и очевидца Айялы их нет. Кандидат на картинку: миниатюра Froissart (BnF fr. 2643, f. 72), PD на Commons. [16.10.2026] Правки владельца: хук переписан, история начинается с Нуну и не скомкана (лимит расширен). | U10: =IF($A10="",0,IFERROR(MATCH($A10,Тексты!$A$1:$A$61,0),0)) -> 10 | V10: =IF($A10="",0,IFERROR(MATCH($A10,Места!$A$1:$A$61,0),0)) -> 10 | W10: =IF($A10="","",IF(COUNTIF($A$2:$A$61,$A10)>1,"дубль id; ","")&IF($B10="","нет эпохи; ","")&IF($C10="","нет уровня; ","")&IF($D10="","нет года; ","")&IF($F10="","нет нити; ","")&IF($H10="","нет важности; ","")&IF($I10="","нет метки; ","")&IF($J10="","нет возраста; ","")&IF($K10="","не указана тяжёлая тема; ","")&IF($M10<IF($C10="frame",2,1),"источников "&$M10&" из "&IF($C10="frame",2,1)&"; ","")&IF($U10=0,"нет строки в «Тексты»; ",IF(INDEX(Тексты!$C$1:$C$61,$U10)=0,"нет крючок EN; ",IF(OR(INDEX(Тексты!$C$1:$C$61,$U10)<1,INDEX(Тексты!$C$1:$C$61,$U10)>12),"крючок EN "&INDEX(Тексты!$C$1:$C$61,$U10)&" сл. (нужно 1–12); ",""))&IF(INDEX(Тексты!$E$1:$E$61,$U10)=0,"нет крючок PT; ",IF(OR(INDEX(Тексты!$E$1:$E$61,$U10)<1,INDEX(Тексты!$E$1:$E$61,$U10)>12),"крючок PT "&INDEX(Тексты!$E$1:$E$61,$U10)&" сл. (нужно 1–12); ",""))&IF(INDEX(Тексты!$O$1:$O$61,$U10)=0,"нет крючок RU; ",IF(OR(INDEX(Тексты!$O$1:$O$61,$U10)<1,INDEX(Тексты!$O$1:$O$61,$U10)>12),"крючок RU "&INDEX(Тексты!$O$1:$O$61,$U10)&" сл. (нужно 1–12); ",""))&IF(INDEX(Тексты!$G$1:$G$61,$U10)=0,"нет история EN; ",IF(OR(INDEX(Тексты!$G$1:$G$61,$U10)<40,INDEX(Тексты!$G$1:$G$61,$U10)>90),"история EN "&INDEX(Тексты!$G$1:$G$61,$U10)&" сл. (нужно 40–90); ",""))&IF(INDEX(Тексты!$I$1:$I$61,$U10)=0,"нет история PT; ",IF(OR(INDEX(Тексты!$I$1:$I$61,$U10)<40,INDEX(Тексты!$I$1:$I$61,$U10)>90),"история PT "&INDEX(Тексты!$I$1:$I$61,$U10)&" сл. (нужно 40–90); ",""))&IF(INDEX(Тексты!$Q$1:$Q$61,$U10)=0,"нет история RU; ",IF(OR(INDEX(Тексты!$Q$1:$Q$61,$U10)<40,INDEX(Тексты!$Q$1:$Q$61,$U10)>90),"история RU "&INDEX(Тексты!$Q$1:$Q$61,$U10)&" сл. (нужно 40–90); ",""))&IF(INDEX(Тексты!$K$1:$K$61,$U10)=0,"нет подробнее EN; ",IF(OR(INDEX(Тексты!$K$1:$K$61,$U10)<1,INDEX(Тексты!$K$1:$K$61,$U10)>250),"подробнее EN "&INDEX(Тексты!$K$1:$K$61,$U10)&" сл. (нужно 1–250); ",""))&IF(INDEX(Тексты!$M$1:$M$61,$U10)=0,"нет подробнее PT; ",IF(OR(INDEX(Тексты!$M$1:$M$61,$U10)<1,INDEX(Тексты!$M$1:$M$61,$U10)>250),"подробнее PT "&INDEX(Тексты!$M$1:$M$61,$U10)&" сл. (нужно 1–250); ",""))&IF(INDEX(Тексты!$S$1:$S$61,$U10)=0,"нет подробнее RU; ",IF(OR(INDEX(Тексты!$S$1:$S$61,$U10)<1,INDEX(Тексты!$S$1:$S$61,$U10)>250),"подробнее RU "&INDEX(Тексты!$S$1:$S$61,$U10)&" сл. (нужно 1–250); ","")))&IF($V10=0,"нет строки в «Места»; ",IF(OR(INDEX(Места!$B$1:$B$61,$V10)="",INDEX(Места!$C$1:$C$61,$V10)="",INDEX(Места!$Q$1:$Q$61,$V10)=""),"нет названия EN/PT/RU; ","")&IF(OR(INDEX(Места!$D$1:$D$61,$V10)="",INDEX(Места!$E$1:$E$61,$V10)="",INDEX(Места!$R$1:$R$61,$V10)=""),"нет slug EN/PT/RU; ","")&IF(INDEX(Места!$K$1:$K$61,$V10)="","нет моста в сегодня; ","")&IF(OR(INDEX(Места!$O$1:$O$61,$V10)="",INDEX(Места!$O$1:$O$61,$V10)="TODO"),"нет сайта моста; ","")&IF(INDEX(Места!$P$1:$P$61,$V10)<>"да","координаты не проверены; ",""))&IF(AND($L10="готово",OR($R10="",$S10="")),"нет рецензента/даты; ","")) -> координаты не проверены;
A11: terramoto-1755 | B11: pombal-e-terramoto | C11: frame | D11: 1755 | E11: Землетрясение 1755 | F11: natureza | H11: 3 | I11: documented | J11: 12 | K11: да | L11: черновик | M11: =IF($A11="","",COUNTIFS(Источники!$A$2:$A$200,$A11,Источники!$G$2:$G$200,"нашли")) -> 7 | N11: =IF($A11="","",IF($W11="","OK",$W11)) -> координаты не проверены; | O11: aljubarrota-1385 | T11: Текст переписан (v2): король, дочь, палатки, Помбал. Письмо короля: один источник. Кант и Вольтер убраны из «Подробнее» ради места. Высоту цунами в Лиссабоне не нашли: числа в тексте нет. [16.10.2026] Кандидат на картинку записан в листе «Картинки» (файл ещё не скачан). Вид и кадрирование не проверялись. | U11: =IF($A11="",0,IFERROR(MATCH($A11,Тексты!$A$1:$A$61,0),0)) -> 11 | V11: =IF($A11="",0,IFERROR(MATCH($A11,Места!$A$1:$A$61,0),0)) -> 11 | W11: =IF($A11="","",IF(COUNTIF($A$2:$A$61,$A11)>1,"дубль id; ","")&IF($B11="","нет эпохи; ","")&IF($C11="","нет уровня; ","")&IF($D11="","нет года; ","")&IF($F11="","нет нити; ","")&IF($H11="","нет важности; ","")&IF($I11="","нет метки; ","")&IF($J11="","нет возраста; ","")&IF($K11="","не указана тяжёлая тема; ","")&IF($M11<IF($C11="frame",2,1),"источников "&$M11&" из "&IF($C11="frame",2,1)&"; ","")&IF($U11=0,"нет строки в «Тексты»; ",IF(INDEX(Тексты!$C$1:$C$61,$U11)=0,"нет крючок EN; ",IF(OR(INDEX(Тексты!$C$1:$C$61,$U11)<1,INDEX(Тексты!$C$1:$C$61,$U11)>12),"крючок EN "&INDEX(Тексты!$C$1:$C$61,$U11)&" сл. (нужно 1–12); ",""))&IF(INDEX(Тексты!$E$1:$E$61,$U11)=0,"нет крючок PT; ",IF(OR(INDEX(Тексты!$E$1:$E$61,$U11)<1,INDEX(Тексты!$E$1:$E$61,$U11)>12),"крючок PT "&INDEX(Тексты!$E$1:$E$61,$U11)&" сл. (нужно 1–12); ",""))&IF(INDEX(Тексты!$O$1:$O$61,$U11)=0,"нет крючок RU; ",IF(OR(INDEX(Тексты!$O$1:$O$61,$U11)<1,INDEX(Тексты!$O$1:$O$61,$U11)>12),"крючок RU "&INDEX(Тексты!$O$1:$O$61,$U11)&" сл. (нужно 1–12); ",""))&IF(INDEX(Тексты!$G$1:$G$61,$U11)=0,"нет история EN; ",IF(OR(INDEX(Тексты!$G$1:$G$61,$U11)<40,INDEX(Тексты!$G$1:$G$61,$U11)>90),"история EN "&INDEX(Тексты!$G$1:$G$61,$U11)&" сл. (нужно 40–90); ",""))&IF(INDEX(Тексты!$I$1:$I$61,$U11)=0,"нет история PT; ",IF(OR(INDEX(Тексты!$I$1:$I$61,$U11)<40,INDEX(Тексты!$I$1:$I$61,$U11)>90),"история PT "&INDEX(Тексты!$I$1:$I$61,$U11)&" сл. (нужно 40–90); ",""))&IF(INDEX(Тексты!$Q$1:$Q$61,$U11)=0,"нет история RU; ",IF(OR(INDEX(Тексты!$Q$1:$Q$61,$U11)<40,INDEX(Тексты!$Q$1:$Q$61,$U11)>90),"история RU "&INDEX(Тексты!$Q$1:$Q$61,$U11)&" сл. (нужно 40–90); ",""))&IF(INDEX(Тексты!$K$1:$K$61,$U11)=0,"нет подробнее EN; ",IF(OR(INDEX(Тексты!$K$1:$K$61,$U11)<1,INDEX(Тексты!$K$1:$K$61,$U11)>250),"подробнее EN "&INDEX(Тексты!$K$1:$K$61,$U11)&" сл. (нужно 1–250); ",""))&IF(INDEX(Тексты!$M$1:$M$61,$U11)=0,"нет подробнее PT; ",IF(OR(INDEX(Тексты!$M$1:$M$61,$U11)<1,INDEX(Тексты!$M$1:$M$61,$U11)>250),"подробнее PT "&INDEX(Тексты!$M$1:$M$61,$U11)&" сл. (нужно 1–250); ",""))&IF(INDEX(Тексты!$S$1:$S$61,$U11)=0,"нет подробнее RU; ",IF(OR(INDEX(Тексты!$S$1:$S$61,$U11)<1,INDEX(Тексты!$S$1:$S$61,$U11)>250),"подробнее RU "&INDEX(Тексты!$S$1:$S$61,$U11)&" сл. (нужно 1–250); ","")))&IF($V11=0,"нет строки в «Места»; ",IF(OR(INDEX(Места!$B$1:$B$61,$V11)="",INDEX(Места!$C$1:$C$61,$V11)="",INDEX(Места!$Q$1:$Q$61,$V11)=""),"нет названия EN/PT/RU; ","")&IF(OR(INDEX(Места!$D$1:$D$61,$V11)="",INDEX(Места!$E$1:$E$61,$V11)="",INDEX(Места!$R$1:$R$61,$V11)=""),"нет slug EN/PT/RU; ","")&IF(INDEX(Места!$K$1:$K$61,$V11)="","нет моста в сегодня; ","")&IF(OR(INDEX(Места!$O$1:$O$61,$V11)="",INDEX(Места!$O$1:$O$61,$V11)="TODO"),"нет сайта моста; ","")&IF(INDEX(Места!$P$1:$P$61,$V11)<>"да","координаты не проверены; ",""))&IF(AND($L11="готово",OR($R11="",$S11="")),"нет рецензента/даты; ","")) -> координаты не проверены;
A12: ponte-das-barcas-1809 | B12: pombal-e-terramoto | C12: story | D12: 1809 | E12: Мост из лодок: бегство из Порту 29 марта 1809 | F12: gente-como-nos | H12: 2 | I12: documented | J12: 12 | K12: да | L12: черновик | M12: =IF($A12="","",COUNTIFS(Источники!$A$2:$A$200,$A12,Источники!$G$2:$G$200,"нашли")) -> 6 | N12: =IF($A12="","",IF($W12="","OK",$W12)) -> нет сайта моста; координаты не проверены; | O12: motim-companhia-1757, torres-vedras-1810 | T12: Тяжёлая тема: массовая гибель людей. Число погибших: ≈4000 (Wikipedia, список бедствий) и ≈5000 (Infopédia): в тексте диапазон 4000–5000. Скульптор Teixeira Lopes и дата 1897: Wikipedia, нужен второй источник. «Мост построен в 1806»: Infopédia. Исправление к списку: «Alminhas da Ponte» — бронзовый барельеф 1897, не «свечи из старины»; ежегодные процессии упомянуты слабым источником (audiala), в текст не включены. Координаты места и памятника не заполнены: найти. Нет второй нити. [Перепроверка 16.10.2026] Запасной мост: церковь São José das Taipas (Rua das Taipas 89, адрес из слабого источника). Рядом с барельефом есть современный монумент Souto de Moura (2009, DN): уточнить название и использовать как ориентир. [16.10.2026] Кандидат на картинку записан в листе «Картинки» (файл ещё не скачан). Вид и кадрирование не проверялись. [16.10.2026] Правки владельца: новый хук; история и «Подробнее» больше не дублируют друг друга. | U12: =IF($A12="",0,IFERROR(MATCH($A12,Тексты!$A$1:$A$61,0),0)) -> 12 | V12: =IF($A12="",0,IFERROR(MATCH($A12,Места!$A$1:$A$61,0),0)) -> 12 | W12: =IF($A12="","",IF(COUNTIF($A$2:$A$61,$A12)>1,"дубль id; ","")&IF($B12="","нет эпохи; ","")&IF($C12="","нет уровня; ","")&IF($D12="","нет года; ","")&IF($F12="","нет нити; ","")&IF($H12="","нет важности; ","")&IF($I12="","нет метки; ","")&IF($J12="","нет возраста; ","")&IF($K12="","не указана тяжёлая тема; ","")&IF($M12<IF($C12="frame",2,1),"источников "&$M12&" из "&IF($C12="frame",2,1)&"; ","")&IF($U12=0,"нет строки в «Тексты»; ",IF(INDEX(Тексты!$C$1:$C$61,$U12)=0,"нет крючок EN; ",IF(OR(INDEX(Тексты!$C$1:$C$61,$U12)<1,INDEX(Тексты!$C$1:$C$61,$U12)>12),"крючок EN "&INDEX(Тексты!$C$1:$C$61,$U12)&" сл. (нужно 1–12); ",""))&IF(INDEX(Тексты!$E$1:$E$61,$U12)=0,"нет крючок PT; ",IF(OR(INDEX(Тексты!$E$1:$E$61,$U12)<1,INDEX(Тексты!$E$1:$E$61,$U12)>12),"крючок PT "&INDEX(Тексты!$E$1:$E$61,$U12)&" сл. (нужно 1–12); ",""))&IF(INDEX(Тексты!$O$1:$O$61,$U12)=0,"нет крючок RU; ",IF(OR(INDEX(Тексты!$O$1:$O$61,$U12)<1,INDEX(Тексты!$O$1:$O$61,$U12)>12),"крючок RU "&INDEX(Тексты!$O$1:$O$61,$U12)&" сл. (нужно 1–12); ",""))&IF(INDEX(Тексты!$G$1:$G$61,$U12)=0,"нет история EN; ",IF(OR(INDEX(Тексты!$G$1:$G$61,$U12)<40,INDEX(Тексты!$G$1:$G$61,$U12)>90),"история EN "&INDEX(Тексты!$G$1:$G$61,$U12)&" сл. (нужно 40–90); ",""))&IF(INDEX(Тексты!$I$1:$I$61,$U12)=0,"нет история PT; ",IF(OR(INDEX(Тексты!$I$1:$I$61,$U12)<40,INDEX(Тексты!$I$1:$I$61,$U12)>90),"история PT "&INDEX(Тексты!$I$1:$I$61,$U12)&" сл. (нужно 40–90); ",""))&IF(INDEX(Тексты!$Q$1:$Q$61,$U12)=0,"нет история RU; ",IF(OR(INDEX(Тексты!$Q$1:$Q$61,$U12)<40,INDEX(Тексты!$Q$1:$Q$61,$U12)>90),"история RU "&INDEX(Тексты!$Q$1:$Q$61,$U12)&" сл. (нужно 40–90); ",""))&IF(INDEX(Тексты!$K$1:$K$61,$U12)=0,"нет подробнее EN; ",IF(OR(INDEX(Тексты!$K$1:$K$61,$U12)<1,INDEX(Тексты!$K$1:$K$61,$U12)>250),"подробнее EN "&INDEX(Тексты!$K$1:$K$61,$U12)&" сл. (нужно 1–250); ",""))&IF(INDEX(Тексты!$M$1:$M$61,$U12)=0,"нет подробнее PT; ",IF(OR(INDEX(Тексты!$M$1:$M$61,$U12)<1,INDEX(Тексты!$M$1:$M$61,$U12)>250),"подробнее PT "&INDEX(Тексты!$M$1:$M$61,$U12)&" сл. (нужно 1–250); ",""))&IF(INDEX(Тексты!$S$1:$S$61,$U12)=0,"нет подробнее RU; ",IF(OR(INDEX(Тексты!$S$1:$S$61,$U12)<1,INDEX(Тексты!$S$1:$S$61,$U12)>250),"подробнее RU "&INDEX(Тексты!$S$1:$S$61,$U12)&" сл. (нужно 1–250); ","")))&IF($V12=0,"нет строки в «Места»; ",IF(OR(INDEX(Места!$B$1:$B$61,$V12)="",INDEX(Места!$C$1:$C$61,$V12)="",INDEX(Места!$Q$1:$Q$61,$V12)=""),"нет названия EN/PT/RU; ","")&IF(OR(INDEX(Места!$D$1:$D$61,$V12)="",INDEX(Места!$E$1:$E$61,$V12)="",INDEX(Места!$R$1:$R$61,$V12)=""),"нет slug EN/PT/RU; ","")&IF(INDEX(Места!$K$1:$K$61,$V12)="","нет моста в сегодня; ","")&IF(OR(INDEX(Места!$O$1:$O$61,$V12)="",INDEX(Места!$O$1:$O$61,$V12)="TODO"),"нет сайта моста; ","")&IF(INDEX(Места!$P$1:$P$61,$V12)<>"да","координаты не проверены; ",""))&IF(AND($L12="готово",OR($R12="",$S12="")),"нет рецензента/даты; ","")) -> нет сайта моста; координаты не проверены;
